<?xml version="1.0" ?>

<robot name="PyramidObjectModel">

	<link name="ground">
		<inertial>
			<origin xyz="0.0 0.0 0.0" rpy="0 0 0" />
			<mass value="0.001" />
			<inertia ixx="0.01" iyy="0.01" izz="0.01" ixy="0" ixz="0" iyz="0" />
		</inertial>
	</link>
	<link name="lpx">
		<inertial>
			<origin xyz="0.0 0.0 0.0" rpy="0 0 0" />
			<mass value="0.001" />
			<inertia ixx="0.00001" iyy="0.00001" izz="0.00001" ixy="0" ixz="0" iyz="0" />
		</inertial>
	</link>
	<link name="lpy">
		<inertial>
			<origin xyz="0.0 0.0 0.0" rpy="0 0 0" />
			<mass value="0.001" />
			<inertia ixx="0.00001" iyy="0.00001" izz="0.00001" ixy="0" ixz="0" iyz="0" />
		</inertial>
	</link>
	<link name="lpz">
		<inertial>
			<origin xyz="0.0 0.0 0.0" rpy="0 0 0" />
			<mass value="0.001" />
			<inertia ixx="0.00001" iyy="0.00001" izz="0.00001" ixy="0" ixz="0" iyz="0" />
		</inertial>
	</link>
	<link name="object">
		<inertial>
			<origin xyz="0.0 0.0 0.0" rpy="0 0 0" />
			<mass value="1.000" />
			<inertia ixx="0.003" iyy="0.003" izz="0.001" ixy="0" ixz="0" iyz="0" />
		</inertial>
	    <visual>
	        <origin xyz="0.0 0.0 -0.15" rpy="0 0 0" />
	        <geometry>
	        	<!-- <pyramid num_sides="40" height="0.3" base_size="0.02726"/> -->
	        	<!-- <pyramid num_sides="35" height="0.3" base_size="0.0311775"/> -->
	        	<!-- <pyramid num_sides="30" height="0.3" base_size="0.036409"/> -->
	        	<!-- <pyramid num_sides="25" height="0.3" base_size="0.04376178"/> -->
	        	<!-- <pyramid num_sides="20" height="0.3" base_size="0.0548659"/> -->
	        	<!-- <pyramid num_sides="15" height="0.3" base_size="0.0736317"/> -->
	        	<!-- <pyramid num_sides="10" height="0.3" base_size="0.1126"/> -->
	        	<!-- <pyramid num_sides="9" height="0.3" base_size="0.1261"/> -->
	        	<!-- <pyramid num_sides="8" height="0.3" base_size="0.1435"/> -->
	        	<!-- <pyramid num_sides="7" height="0.3" base_size="0.1668"/> -->
	        	<!-- <pyramid num_sides="6" height="0.3" base_size="0.2"/> -->
	        	<!-- <pyramid num_sides="5" height="0.3" base_size="0.2517"/> -->
	        	<!-- <pyramid num_sides="4" height="0.3" base_size="0.3464"/> -->
	        	<pyramid num_sides="3" height="0.3" base_size="0.6"/>
	        </geometry>
	        <material name="material_brown">
		        <!-- <color rgba="0.6 0.5 0.5 1.0" /> -->
		        <color rgba="0.9 0.9 0.9 1.0" />
	        </material>
	    </visual>
	</link>

	<joint name="jpx" type="prismatic">
		<parent link="ground" />
		<child link="lpx" />
		<origin xyz="0.0 0.0 0.0" rpy="0.0 0.0 0.0" />
		<axis xyz="1 0 0" />
		<limit lower="-0.06" upper="0.0" effort="21.3" velocity="1.0" />
	</joint>
	<joint name="jpy" type="prismatic">
		<parent link="lpx" />
		<child link="lpy" />
		<origin xyz="0.0 0.0 0.0" rpy="0.0 0.0 0.0" />
		<axis xyz="0 1 0" />
		<limit lower="-0.06" upper="0.0" effort="21.3" velocity="1.0" />
	</joint>
	<joint name="jpz" type="prismatic">
		<parent link="lpy" />
		<child link="lpz" />
		<origin xyz="0.0 0.0 0.0" rpy="0.0 0.0 0.0" />
		<axis xyz="0 0 1" />
		<limit lower="-0.06" upper="0.0" effort="21.3" velocity="1.0" />
	</joint>
	<joint name="jrs" type="spherical">
		<parent link="lpz" />
		<child link="object" />
		<origin xyz="0.0 0.0 0.0" rpy="0.0 0.0 0.0" />
		<axis xyz="1 0 0" />
		<limit lower="-0.06" upper="0.0" effort="21.3" velocity="1.0" />
	</joint>
</robot>

</xml>