<?xml version="1.0" ?>

<robot name="ObjectModel">

	<link name="ground">
		<inertial>
			<origin xyz="0.0 0.0 0.0" rpy="0 0 0" />
			<mass value="0.001" />
			<inertia ixx="0.01" iyy="0.01" izz="0.01" ixy="0" ixz="0" iyz="0" />
		</inertial>
	</link>
	<link name="lz">
		<inertial>
			<origin xyz="0.0 0.0 0.0" rpy="0 0 0" />
			<mass value="0.001" />
			<inertia ixx="0.00001" iyy="0.00001" izz="0.00001" ixy="0" ixz="0" iyz="0" />
		</inertial>
	</link>
	<link name="lx">
		<inertial>
			<origin xyz="0.0 0.0 0.0" rpy="0 0 0" />
			<mass value="0.001" />
			<inertia ixx="0.00001" iyy="0.00001" izz="0.00001" ixy="0" ixz="0" iyz="0" />
		</inertial>
	</link>
	<link name="ly">
		<inertial>
			<origin xyz="0.0 0.0 0.0" rpy="0 0 0" />
			<mass value="0.001" />
			<inertia ixx="0.00001" iyy="0.00001" izz="0.00001" ixy="0" ixz="0" iyz="0" />
		</inertial>
	</link>
	<link name="lrz">
		<inertial>
			<origin xyz="0.0 0.0 0.0" rpy="0 0 0" />
			<mass value="0.001" />
			<inertia ixx="0.00001" iyy="0.00001" izz="0.00001" ixy="0" ixz="0" iyz="0" />
		</inertial>
	</link>
	<link name="lry">
		<inertial>
			<origin xyz="0.0 0.0 0.0" rpy="0 0 0" />
			<mass value="0.001" />
			<inertia ixx="0.00001" iyy="0.00001" izz="0.00001" ixy="0" ixz="0" iyz="0" />
		</inertial>
	</link>
	<link name="object">
		<inertial>
			<origin xyz="0.0 0.0 0.0" rpy="0 0 0" />
			<mass value="0.500" />
			<inertia ixx="0.0012" iyy="0.0012" izz="0.0022" ixy="0" ixz="0" iyz="0" />
		</inertial>
		<visual>
	        <origin xyz="0.0 0.0 0.0" rpy="0 0 0" />
	        <geometry>
	            <box size="0.35 0.35 0.05" />
	        </geometry>
	        <material name="material_brown">
		        <color rgba="0.9 0.5 0.1 1.0" />
	        </material>
	    </visual>
	    <collision>
	        <origin xyz="0.0 0.0 0.0" rpy="0 0 0" />
	        <geometry>
	            <box size="0.35 0.35 0.05" />
	        </geometry>
	    </collision>
	</link>

	<joint name="j1" type="prismatic">
		<parent link="ground" />
		<child link="lz" />
		<origin xyz="0.0 0.0 0.405" rpy="0.0 0.0 0.0" />
		<axis xyz="0 0 1" />
		<limit lower="-0.06" upper="0.0" effort="21.3" velocity="1.0" />
	</joint>
	<joint name="j2" type="prismatic">
		<parent link="lz" />
		<child link="lx" />
		<origin xyz="0.0 0.0 0.0" rpy="0.0 0.0 0.0" />
		<axis xyz="1 0 0" />
		<limit lower="-0.06" upper="0.0" effort="21.3" velocity="1.0" />
	</joint>
	<joint name="j3" type="prismatic">
		<parent link="lx" />
		<child link="ly" />
		<origin xyz="0.0 0.0 0.0" rpy="0.0 0.0 0.0" />
		<axis xyz="0 1 0" />
		<limit lower="-0.06" upper="0.0" effort="21.3" velocity="1.0" />
	</joint>
	<joint name="j4" type="revolute">
		<parent link="ly" />
		<child link="lrz" />
		<origin xyz="0.0 0.0 0.0" rpy="0.0 0.0 0.0" />
		<axis xyz="0 0 1" />
		<limit lower="-0.06" upper="0.0" effort="21.3" velocity="1.0" />
	</joint>
	<joint name="j5" type="revolute">
		<parent link="lrz" />
		<child link="lry" />
		<origin xyz="0.0 0.0 0.0" rpy="0.0 0.0 0.0" />
		<axis xyz="0 1 0" />
		<limit lower="-0.06" upper="0.0" effort="21.3" velocity="1.0" />
	</joint>
	<joint name="j6" type="revolute">
		<parent link="lry" />
		<child link="object" />
		<origin xyz="0.0 0.0 0.0" rpy="0.0 0.0 0.0" />
		<axis xyz="1 0 0" />
		<limit lower="-0.06" upper="0.0" effort="21.3" velocity="1.0" />
	</joint>

</robot>

</xml>